Workbook

Sheet How To Use
A1: EverGlow commercial cold-call list: Bucks County first, then Montgomery County and Chestnut Hill
A2: Built October 2, 2026 from public web listings. 181 leads with phone numbers, 56 more that need a number.
A4: How to work it
A5: 1. Start at the top. The list is sorted Bucks County first, then by priority (A, B, C), then by town.
A6: 2. Fill in only the yellow columns: Status (dropdown), Date Called, Contact Name, Follow-up Date, Notes.
A7: 3. The Tracker tab counts your statuses automatically.
A8: 4. When you have a spare minute, look up numbers on the Phone Needed tab and move good ones onto the Call List.
A10: Priority
A11: A: owner or GM can say yes fast, or one call covers several properties (bars, restaurant-bars, breweries, wineries, dealerships, hotels, property managers, shopping centers).
A12: B: worth calling, smaller ticket or slower decision (restaurants, cafes, retail, salons, senior living, business districts).
A13: C: networking and referrals rather than a direct sale (churches, chambers of commerce, garden centers).
A15: Read before you dial
... A35: Phone: (267) 853-0058 | EverglowChristmasLightsPA.com

Sheet Call List
A1: # | B1: Priority | C1: Business | D1: Category | E1: Phone | F1: Address | G1: Town | H1: County | I1: Status | J1: Date Called | K1: Contact Name | L1: Follow-up Date | M1: Notes | N1: Call Tip | O1: Source
A2: 1 | B2: A | C2: American Auto Bensalem | D2: Car dealership | E2: (267) 332-0768 | F2: 2580 Bristol Pike | G2: Bensalem | H2: Bucks | I2: Not called | N2: Ask for the general manager. Listing-site numbers can be tracking lines that ring sales. | O2: creditacceptance.com
A3: 2 | B3: A | C3: Blue Sunday Bar & Grill | D3: Restaurant/bar | E3: (215) 883-9988 | F3: 3340 Street Rd | G3: Bensalem | H3: Bucks | I3: Not called | M3: Directory listing: confirm the number on the first call. | N3: Ask for the owner or GM. Call 2-4pm, between lunch and dinner. | O3: city-data.com
A4: 3 | B4: A | C4: Founding Fathers Sports Bar & Grill | D4: Restaurant/bar | E4: (215) 902-9159 | F4: 2900 Street Rd | G4: Bensalem | H4: Bucks | I4: Not called | N4: Ask for the owner or GM. Call 2-4pm, between lunch and dinner. | O4: aaa.com
A5: 4 | B5: A | C5: La Cena Restaurant & Bar | D5: Restaurant/bar | E5: (215) 639-9969 | F5: 2233 Galloway Rd | G5: Bensalem | H5: Bucks | I5: Not called | M5: Directory listing: confirm the number on the first call. | N5: Ask for the owner or GM. Call 2-4pm, between lunch and dinner. | O5: city-data.com
A6: 5 | B6: A | C6: Buckingham Valley Vineyards and Winery | D6: Winery | E6: (215) 794-7188 | F6: 1521 Durham Rd | G6: Buckingham | H6: Bucks | I6: Not called | N6: Ask for the owner. | O6: visitpa.com
A7: 6 | B7: A | C7: BMW of Doylestown | D7: Car dealership | E7: (267) 898-2461 | G7: Doylestown | H7: Bucks | I7: Not called | N7: Ask for the general manager. Listing-site numbers can be tracking lines that ring sales. | O7: caredge.com
A8: 7 | B8: A | C8: Bay Property Management Group (Bucks County) | D8: Property manager (residential + commercial) | E8: (215) 724-4043 | F8: 107 N Broad St #310 | G8: Doylestown | H8: Bucks | I8: Not called | N8: Ask who handles holiday decor for the properties. Pitch a 3-year locked rate. | O8: baymgmtgroup.com; alt (267) 244-7215 (Dana Anderson x26150)
A9: 8 | B9: A | C9: Chambers 19 Bistro Bar | D9: Restaurant/bar | E9: (215) 348-1940 | F9: 19 N Main St | G9: Doylestown | H9: Bucks | I9: Not called | N9: Ask for the owner or GM. Call 2-4pm, between lunch and dinner. | O9: aaa.com
A10: 9 | B10: A | C10: Fred Beans Ford Lincoln | D10: Car dealership | E10: (888) 854-8597 | F10: 864 N Easton Rd | G10: Doylestown | H10: Bucks | I10: Not called | N10: Ask for the general manager. Listing-site numbers can be tracking lines that ring sales. | O10: ophelia.sdsu.edu dealer directory
A11: 10 | B11: A | C11: Keystone Motors | D11: Car dealership | E11: (215) 348-9438 | F11: 235 S Main St | G11: Doylestown | H11: Bucks | I11: Not called | N11: Ask for the general manager. Listing-site numbers can be tracking lines that ring sales. | O11: ophelia.sdsu.edu dealer directory
A12: 11 | B12: A | C12: Mainstreet Inn | D12: Hotel | E12: (215) 348-9222 | F12: 625 N Main St | G12: Doylestown | H12: Bucks | I12: Not called | N12: Ask for the general manager. | O12: hotels.com
A13: 12 | B13: A | C13: Maxwell's on Main | D13: Restaurant/bar | E13: (215) 340-1880 | F13: 37 N Main St | G13: Doylestown | H13: Bucks | I13: Not called | N13: Ask for the owner or GM. Call 2-4pm, between lunch and dinner. | O13: aaa.com
A14: 13 | B14: A | C14: The Doylestown Inn / The Hattery Stove & Still | D14: Hotel/restaurant | E14: (215) 345-1527 | F14: 18 W State St | G14: Doylestown | H14: Bucks | I14: Not called | N14: Ask for the general manager. | O14: thinkreservations.com / aaa.com
A15: 14 | B15: A | C15: Sand Castle Winery | D15: Winery | E15: (800) 722-9463 | F15: 755 River Rd | G15: Erwinna | H15: Bucks | I15: Not called | N15: Ask for the owner. | O15: visitpa.com
A16: 15 | B16: A | C16: Bucks Crossing Shopping Center (BET Investments - Michael Markman) | D16: Shopping center | E16: (215) 938-7115 | F16: Street Rd & Bustleton Pike | G16: Feasterville | H16: Bucks | I16: Not called | N16: Ask who handles holiday decor for the properties. Pitch a 3-year locked rate. | O16: betinvestments.com
A17: 16 | B17: A | C17: Jamison Grille | D17: Restaurant/bar | E17: (215) 343-0350 | F17: 2600 York Rd | G17: Jamison | H17: Bucks | I17: Not called | M17: Directory listing: confirm the number on the first call. | N17: Ask for the owner or GM. Call 2-4pm, between lunch and dinner. | O17: city-data.com
A18: 17 | B18: A | C18: Jamison Pourhouse | D18: Restaurant/bar | E18: (267) 483-5179 | F18: 2160 York Rd | G18: Jamison | H18: Bucks | I18: Not called | M18: Directory listing: confirm the number on the first call. | N18: Ask for the owner or GM. Call 2-4pm, between lunch and dinner. | O18: city-data.com
A19: 18 | B19: A | C19: Rushland Ridge Vineyards | D19: Winery | E19: (215) 598-0251 | F19: 2665 Rushland Rd | G19: Jamison | H19: Bucks | I19: Not called | N19: Ask for the owner. | O19: visitpa.com
A20: 19 | B20: A | C20: Davis Acura | D20: Car dealership | E20: (267) 689-8049 | F20: 2051 E Lincoln Hwy | G20: Langhorne | H20: Bucks | I20: Not called | N20: Ask for the general manager. Listing-site numbers can be tracking lines that ring sales. | O20: kbb.com
A21: 20 | B21: A | C21: Fred Beans Ford of Langhorne | D21: Car dealership | E21: (267) 930-5654 | F21: 1939 E Lincoln Hwy | G21: Langhorne | H21: Bucks | I21: Not called | N21: Ask for the general manager. Listing-site numbers can be tracking lines that ring sales. | O21: kbb.com
A22: 21 | B22: A | C22: Fred Beans Kia of Langhorne | D22: Car dealership | E22: (215) 945-8001 | F22: 1801 E Lincoln Hwy | G22: Langhorne | H22: Bucks | I22: Not called | N22: Ask for the general manager. Listing-site numbers can be tracking lines that ring sales. | O22: kbb.com
A23: 22 | B23: A | C23: G & E Motors | D23: Car dealership | E23: (267) 560-5519 | F23: 451 E Lincoln Hwy | G23: Langhorne | H23: Bucks | I23: Not called | N23: Ask for the general manager. Listing-site numbers can be tracking lines that ring sales. | O23: kbb.com
A24: 23 | B24: A | C24: JB Dawson's Restaurant & Bar | D24: Restaurant/bar | E24: (215) 702-8119 | F24: 92 N Flowers Mill Rd | G24: Langhorne | H24: Bucks | I24: Not called | N24: Ask for the owner or GM. Call 2-4pm, between lunch and dinner. | O24: aaa.com
A25: 24 | B25: A | C25: Team Toyota of Langhorne | D25: Car dealership | E25: (267) 817-1549 | F25: 746 E Lincoln Hwy | G25: Langhorne | H25: Bucks | I25: Not called | N25: Ask for the general manager. Listing-site numbers can be tracking lines that ring sales. | O25: kbb.com
A26: 25 | B26: A | C26: Levittown Auto | D26: Car dealership | E26: (215) 547-9494 | F26: 4033 New Rodgers Rd | G26: Levittown | H26: Bucks | I26: Not called | N26: Ask for the general manager. Listing-site numbers can be tracking lines that ring sales. | O26: kbb.com
A27: 26 | B27: A | C27: Centre Bridge Inn | D27: Hotel/restaurant | E27: (215) 862-9139 | F27: 2998 N River Rd | G27: New Hope | H27: Bucks | I27: Not called | N27: Ask for the general manager. | O27: successfulmeetings.com
A28: 27 | B28: A | C28: GreenHouse New Hope | D28: Restaurant/bar | E28: (215) 693-1657 | F28: 90 S Main St | G28: New Hope | H28: Bucks | I28: Not called | N28: Ask for the owner or GM. Call 2-4pm, between lunch and dinner. | O28: aaa.com
A29: 28 | B29: A | C29: Hotel du Village | D29: Hotel/restaurant | E29: (215) 330-2700 | F29: 2535 River Rd | G29: New Hope | H29: Bucks | I29: Not called | N29: Ask for the general manager. | O29: meetings-conventions.com
A30: 29 | B30: A | C30: John and Peter's Place | D30: Bar/music venue | E30: (215) 862-5981 | F30: 96 S Main St | G30: New Hope | H30: Bucks | I30: Not called | N30: Ask for the owner or GM. Call 2-4pm, between lunch and dinner. | O30: explorepahistory.com
... A35: 34 | B35: A | C35: Bill Marsh Ford / Fred Beans Ford of Newtown | D35: Car dealership | E35: (215) 968-3806 | F35: 10 N Sycamore St | G35: Newtown | H35: Bucks | I35: Not called | N35: Ask for the general manager. Listing-site numbers can be tracking lines that ring sales. | O35: ophelia.sdsu.edu dealer directory; caredge.com lists (855) 818-3875
A36: 35 | B36: A | C36: Black Horse Tavern | D36: Restaurant/bar | E36: (215) 579-6152 | F36: 101 S State St | G36: Newtown | H36: Bucks | I36: Not called | M36: Directory listing: confirm the number on the first call. | N36: Ask for the owner or GM. Call 2-4pm, between lunch and dinner. | O36: city-data.com
A37: 36 | B37: A | C37: Crossing Vineyards and Winery | D37: Winery | E37: (215) 493-6500 | F37: 1853 Wrightstown Rd | G37: Newtown | H37: Bucks | I37: Not called | N37: Ask for the owner. | O37: visitpa.com
A38: 37 | B38: A | C38: Ferino Bros Auto Sales | D38: Car dealership | E38: (215) 918-7548 | G38: Newtown | H38: Bucks | I38: Not called | N38: Ask for the general manager. Listing-site numbers can be tracking lines that ring sales. | O38: caredge.com
A39: 38 | B39: A | C39: Relic on State Street | D39: Restaurant/bar | E39: (267) 759-6641 | F39: 101 S State St | G39: Newtown | H39: Bucks | I39: Not called | N39: Ask for the owner or GM. Call 2-4pm, between lunch and dinner. | O39: aaa.com
A40: 39 | B40: A | C40: Rose Bank Winery | D40: Winery | E40: (215) 860-5899 | F40: 258 Durham Rd (Rt 413) | G40: Newtown | H40: Bucks | I40: Not called | N40: Ask for the owner. | O40: visitpa.com
A41: 40 | B41: A | C41: Bishop Estate Vineyard and Winery | D41: Winery | E41: (215) 249-3559 | F41: 2730 Hilltown Pike | G41: Perkasie | H41: Bucks | I41: Not called | N41: Ask for the owner. | O41: visitpa.com
A42: 41 | B42: A | C42: Free Will Brewing Co. | D42: Brewery/taproom | E42: (267) 354-0813 | F42: 410 E Walnut St | G42: Perkasie | H42: Bucks | I42: Not called | N42: Ask for the owner or GM. Call 2-4pm, between lunch and dinner. | O42: visitpa.com
A43: 42 | B43: A | C43: Bucks County Brewery | D43: Brewery | E43: (609) 439-2468 | F43: 31 Appletree Ln | G43: Pipersville | H43: Bucks | I43: Not called | N43: Ask for the owner or GM. Call 2-4pm, between lunch and dinner. | O43: visitpa.com
A44: 43 | B44: A | C44: Grain Craft Bar + Kitchen | D44: Restaurant/bar | E44: (215) 538-7001 | F44: 225 W Broad St | G44: Quakertown | H44: Bucks | I44: Not called | N44: Ask for the owner or GM. Call 2-4pm, between lunch and dinner. | O44: quakertown.org
...

Sheet Phone Needed
A1: # | B1: Business | C1: Category | D1: Address | E1: Town | F1: County | G1: Why it is worth a lookup | H1: Phone (fill in)
A2: 1 | B2: Bristol Antique Mart | C2: Retail - antiques | D2: Mill St | E2: Bristol | F2: Bucks | G2: Downtown Bristol
A3: 2 | B3: ITRI Wood Fired | C3: Restaurant/bar | D3: Mill St | E3: Bristol | F3: Bucks | G3: Downtown Bristol
A4: 3 | B4: 1720 Bar & Restaurant | C4: Restaurant/bar | D4: 136 E Butler Ave | E4: Chalfont | F4: Bucks | G4: Bar, owner decides
A5: 4 | B5: Embers Smokehouse and Tap | C5: Restaurant/bar | D5: 237 W Butler Ave | E5: Chalfont | F5: Bucks | G5: Bar, owner decides
A6: 5 | B6: Skyline Tavern & Restaurant | C6: Restaurant/bar | D6: 241 W Butler Ave | E6: Chalfont | F6: Bucks | G6: 40-year local tavern
A7: 6 | B7: The Talking Teacup | C7: Restaurant/tea room | D7: 301 W Butler Ave | E7: Chalfont | F7: Bucks | G7: Holiday teas
A8: 7 | B8: Busy Bee Toys | C8: Retail - toys | D8: 58 E State St | E8: Doylestown | F8: Bucks | G8: Holiday-season retailer
A9: 8 | B9: Cross Culture | C9: Restaurant | D9: 62-64 W State St | E9: Doylestown | F9: Bucks | G9: Downtown Doylestown
A10: 9 | B10: Doyle's Down the Alley | C10: Bar | D10: 52 E State St | E10: Doylestown | F10: Bucks | G10: Downtown Doylestown
A11: 10 | B11: Doylestown Business and Community Alliance | C11: Business district association | D11: 17 W State St | E11: Doylestown | F11: Bucks | G11: Runs downtown events; could hire for streetscape lighting
A12: 11 | B12: Faulkner Honda of Doylestown | C12: Car dealership | D12: 4311 W Swamp Rd | E12: Doylestown | F12: Bucks | G12: Big lot on a busy road
A13: 12 | B13: Fred Beans Chevrolet | C13: Car dealership | D13: 845 N Easton Rd | E13: Doylestown | F13: Bucks | G13: Fred Beans group
... A57: 56 | B57: Bistro Albertino | C57: Restaurant | D57: 634 York Rd | E57: Willow Grove | F57: Montgomery | G57: Independent restaurant

Sheet Tracker
A1: Call progress (updates automatically from the Status column on Call List)
A3: Status | B3: Count | C3: Share of list
A4: Not called | B4: =COUNTIF('Call List'!$I$2:$I$482,A4) | C4: =IF($B$13=0,0,B4/$B$13)
A5: No answer | B5: =COUNTIF('Call List'!$I$2:$I$482,A5) | C5: =IF($B$13=0,0,B5/$B$13)
A6: Left voicemail | B6: =COUNTIF('Call List'!$I$2:$I$482,A6) | C6: =IF($B$13=0,0,B6/$B$13)
A7: Call back | B7: =COUNTIF('Call List'!$I$2:$I$482,A7) | C7: =IF($B$13=0,0,B7/$B$13)
A8: Interested - visit/quote | B8: =COUNTIF('Call List'!$I$2:$I$482,A8) | C8: =IF($B$13=0,0,B8/$B$13)
A9: Quote sent | B9: =COUNTIF('Call List'!$I$2:$I$482,A9) | C9: =IF($B$13=0,0,B9/$B$13)
A10: Booked | B10: =COUNTIF('Call List'!$I$2:$I$482,A10) | C10: =IF($B$13=0,0,B10/$B$13)
A11: Not interested | B11: =COUNTIF('Call List'!$I$2:$I$482,A11) | C11: =IF($B$13=0,0,B11/$B$13)
A12: Wrong number / closed | B12: =COUNTIF('Call List'!$I$2:$I$482,A12) | C12: =IF($B$13=0,0,B12/$B$13)
A13: Total leads | B13: =COUNTA('Call List'!$C$2:$C$482)
A15: Leads by county
A16: County | B16: Leads | C16: Booked
A17: Bucks | B17: =COUNTIF('Call List'!$H$2:$H$482,A17) | C17: =COUNTIFS('Call List'!$H$2:$H$482,A17,'Call List'!$I$2:$I$482,"Booked")
A18: Bucks/Montgomery | B18: =COUNTIF('Call List'!$H$2:$H$482,A18) | C18: =COUNTIFS('Call List'!$H$2:$H$482,A18,'Call List'!$I$2:$I$482,"Booked")
A19: Montgomery | B19: =COUNTIF('Call List'!$H$2:$H$482,A19) | C19: =COUNTIFS('Call List'!$H$2:$H$482,A19,'Call List'!$I$2:$I$482,"Booked")
A20: Philadelphia | B20: =COUNTIF('Call List'!$H$2:$H$482,A20) | C20: =COUNTIFS('Call List'!$H$2:$H$482,A20,'Call List'!$I$2:$I$482,"Booked")
A23: Leads by priority
A24: Priority | B24: Leads | C24: Booked
A25: A | B25: =COUNTIF('Call List'!$B$2:$B$482,A25) | C25: =COUNTIFS('Call List'!$B$2:$B$482,A25,'Call List'!$I$2:$I$482,"Booked")
A26: B | B26: =COUNTIF('Call List'!$B$2:$B$482,A26) | C26: =COUNTIFS('Call List'!$B$2:$B$482,A26,'Call List'!$I$2:$I$482,"Booked")
A27: C | B27: =COUNTIF('Call List'!$B$2:$B$482,A27) | C27: =COUNTIFS('Call List'!$B$2:$B$482,A27,'Call List'!$I$2:$I$482,"Booked")
